<?xml version='1.0' encoding='utf-8'?>
<robot name="humanoidV3_half">
    <link name="ankel1">
        <inertial>
            <origin xyz="-2.8545686614478426e-09 4.961367341405065e-09 0.0008749966309221885" rpy="0.0 -0.0 0.0" />
            <mass value="0.022345050000000005" />
            <inertia ixx="2.6819762642970662e-05" iyy="7.87302233046875e-06" izz="3.4681379687502375e-05" ixy="-4.446922973085077e-20" iyz="-5.815410578492806e-20" ixz="2.0434669852509998e-19" />
        </inertial>
        <visual name="ankel1_visual">
            <origin xyz="-0.03250000285456978 -0.0099999950386329 0.0017499966309222068" rpy="-3.141592653589791 4.267419750902977e-16 -6.881682016646111e-16" />
            <geometry>
                <mesh filename="meshes/ankel1.stl" scale="0.001 0.001 0.001" />
            </geometry>
        </visual>
        <collision name="ankel1_collision">
            <origin xyz="-0.03250000285456978 -0.0099999950386329 0.0017499966309222068" rpy="-3.141592653589791 4.267419750902977e-16 -6.881682016646111e-16" />
            <geometry>
                <mesh filename="meshes/ankel1.stl" scale="0.001 0.001 0.001" />
            </geometry>
        </collision>
    </link>
    <link name="servo2">
        <inertial>
            <origin xyz="-0.009549971198737257 0.0023874887169520755 0.024964922230111784" rpy="0.0 -0.0 0.0" />
            <mass value="0.05780123871717229" />
            <inertia ixx="1.1637489216004055e-05" iyy="1.635538058948426e-05" izz="1.0629005497785803e-05" ixy="6.210436850517169e-08" iyz="-1.4284004757590833e-07" ixz="5.713601902397425e-07" />
        </inertial>
        <visual name="servo2_visual">
            <origin xyz="-0.05000000285457011 0.01674999663092223 0.03599999503863284" rpy="1.570796326794899 -6.881682016646106e-16 -6.486781597980867e-16" />
            <geometry>
                <mesh filename="meshes/servo2.stl" scale="0.001 0.001 0.001" />
            </geometry>
        </visual>
        <collision name="servo2_collision">
            <origin xyz="-0.05000000285457011 0.01674999663092223 0.03599999503863284" rpy="1.570796326794899 -6.881682016646106e-16 -6.486781597980867e-16" />
            <geometry>
                <mesh filename="meshes/servo2.stl" scale="0.001 0.001 0.001" />
            </geometry>
        </collision>
    </link>
    <link name="csmall1">
        <inertial>
            <origin xyz="-3.4451162012061334e-09 4.96135654781682e-09 0.013088698801773916" rpy="0.0 -0.0 0.0" />
            <mass value="0.007517560189288541" />
            <inertia ixx="4.996715608195631e-06" iyy="1.5854743173647894e-06" izz="3.897412167647726e-06" ixy="3.705769144237565e-21" iyz="1.6548906206980893e-18" ixz="-2.315078264183458e-14" />
        </inertial>
        <visual name="csmall1_visual">
            <origin xyz="-0.050000003599628244 -0.011249995575074707 0.049999996884241976" rpy="-3.141592653589791 6.486781597980804e-16 1.4153138822986764e-15" />
            <geometry>
                <mesh filename="meshes/csmall1.stl" scale="0.001 0.001 0.001" />
            </geometry>
        </visual>
        <collision name="csmall1_collision">
            <origin xyz="-0.050000003599628244 -0.011249995575074707 0.049999996884241976" rpy="-3.141592653589791 6.486781597980804e-16 1.4153138822986764e-15" />
            <geometry>
                <mesh filename="meshes/csmall1.stl" scale="0.001 0.001 0.001" />
            </geometry>
        </collision>
    </link>
    <link name="servo4">
        <inertial>
            <origin xyz="-0.0023874888659620196 -0.009549963382800864 0.024964923591852428" rpy="3.111507638930571e-61 -0.0 0.0" />
            <mass value="0.05780123871717229" />
            <inertia ixx="1.6355380589484585e-05" iyy="1.16374892159973e-05" izz="1.0629005497790953e-05" ixy="-6.21043685048261e-08" iyz="5.713601902392325e-07" ixz="1.4284004757467357e-07" />
        </inertial>
        <visual name="servo4_visual">
            <origin xyz="-0.0657499967799339 -0.021999995038632862 -0.02000000359962833" rpy="-3.1415926535897913 -1.5707963267948952 0" />
            <geometry>
                <mesh filename="meshes/servo4.stl" scale="0.001 0.001 0.001" />
            </geometry>
        </visual>
        <collision name="servo4_collision">
            <origin xyz="-0.0657499967799339 -0.021999995038632862 -0.02000000359962833" rpy="-3.1415926535897913 -1.5707963267948952 0" />
            <geometry>
                <mesh filename="meshes/servo4.stl" scale="0.001 0.001 0.001" />
            </geometry>
        </collision>
    </link>
    <link name="csmall2">
        <inertial>
            <origin xyz="-3.5996271297022987e-09 4.37082019244528e-09 0.013088698950758672" rpy="0.0 -0.0 0.0" />
            <mass value="0.0075175601892790555" />
            <inertia ixx="1.5854743173617604e-06" iyy="4.996715608184517e-06" izz="3.897412167641438e-06" ixy="-8.555032767268433e-20" iyz="-2.315089021501888e-14" ixz="2.913793338554793e-19" />
        </inertial>
        <visual name="csmall2_visual">
            <origin xyz="-0.04450000359962822 -0.021749996320132744 0.09899999703325346" rpy="-3.141592653589791 4.271059138961151e-16 1.235205088950724e-15" />
            <geometry>
                <mesh filename="meshes/csmall2.stl" scale="0.001 0.001 0.001" />
            </geometry>
        </visual>
        <collision name="csmall2_collision">
            <origin xyz="-0.04450000359962822 -0.021749996320132744 0.09899999703325346" rpy="-3.141592653589791 4.271059138961151e-16 1.235205088950724e-15" />
            <geometry>
                <mesh filename="meshes/csmall2.stl" scale="0.001 0.001 0.001" />
            </geometry>
        </collision>
    </link>
    <link name="csmall3">
        <inertial>
            <origin xyz="-0.01991129603275702 -1.602994736948915e-09 -0.024749996400372908" rpy="0.0 -0.0 0.0" />
            <mass value="0.007517560189279032" />
            <inertia ixx="3.897412167641516e-06" iyy="4.996715608183798e-06" izz="1.585474317361652e-06" ixy="2.3150932566666244e-14" iyz="-1.5648933700523199e-19" ixz="4.87890977618477e-19" />
        </inertial>
        <visual name="csmall3_visual">
            <origin xyz="-0.14699999845690884 0.021749999087958233 0.01975000359962813" rpy="1.4217821258131194e-15 1.5707963267948954 0" />
            <geometry>
                <mesh filename="meshes/csmall3.stl" scale="0.001 0.001 0.001" />
            </geometry>
        </visual>
        <collision name="csmall3_collision">
            <origin xyz="-0.14699999845690884 0.021749999087958233 0.01975000359962813" rpy="1.4217821258131194e-15 1.5707963267948954 0" />
            <geometry>
                <mesh filename="meshes/csmall3.stl" scale="0.001 0.001 0.001" />
            </geometry>
        </collision>
    </link>
    <link name="Comp1">
        <inertial>
            <origin xyz="-3.5996270320026726e-09 0.005234147832397131 0.007101232491757727" rpy="0.0 -0.0 0.0" />
            <mass value="0.024635392744770463" />
            <inertia ixx="1.4596525160532757e-06" iyy="6.1808355249345025e-06" izz="6.812286694457537e-06" ixy="-3.5914196963582334e-19" iyz="-3.052234876525849e-07" ixz="1.1384122811097797e-18" />
        </inertial>
        <visual name="Comp1_visual">
            <origin xyz="-0.044500003599628184 -0.011309445863593127 0.11331588555303221" rpy="-3.141592653589791 4.270652564688459e-16 1.2352050889507236e-15" />
            <geometry>
                <mesh filename="meshes/Comp1.stl" scale="0.001 0.001 0.001" />
            </geometry>
        </visual>
        <collision name="Comp1_collision">
            <origin xyz="-0.044500003599628184 -0.011309445863593127 0.11331588555303221" rpy="-3.141592653589791 4.270652564688459e-16 1.2352050889507236e-15" />
            <geometry>
                <mesh filename="meshes/Comp1.stl" scale="0.001 0.001 0.001" />
            </geometry>
        </collision>
    </link>
    <link name="servo6">
        <inertial>
            <origin xyz="-0.001510475292044493 -0.059836430778758824 -0.011754290813263743" rpy="0.0 -0.0 0.0" />
            <mass value="0.060699238717172255" />
            <inertia ixx="1.4693730397501246e-05" iyy="1.2227175300402873e-05" izz="2.003750615803962e-05" ixy="-7.085129238231869e-07" iyz="-1.084649952349311e-06" ixz="8.478544706950229e-08" />
        </inertial>
        <visual name="servo6_visual">
            <origin xyz="-0.04655113359962817 -0.2166323182035889 -0.03199999780645821" rpy="-1.5707963267948952 -1.0134561938895422e-15 6.4929979419121075e-16" />
            <geometry>
                <mesh filename="meshes/servo6.stl" scale="0.001 0.001 0.001" />
            </geometry>
        </visual>
        <collision name="servo6_collision">
            <origin xyz="-0.04655113359962817 -0.2166323182035889 -0.03199999780645821" rpy="-1.5707963267948952 -1.0134561938895422e-15 6.4929979419121075e-16" />
            <geometry>
                <mesh filename="meshes/servo6.stl" scale="0.001 0.001 0.001" />
            </geometry>
        </collision>
    </link>
    <link name="csmall4">
        <inertial>
            <origin xyz="-1.751608404987337e-09 2.7840902250275692e-09 0.013088702348303408" rpy="0.0 -0.0 1.9446922743316068e-62" />
            <mass value="0.007517560189288577" />
            <inertia ixx="1.5854743173664902e-06" iyy="4.996715608188542e-06" izz="3.897412167648268e-06" ixy="-4.9763185651190145e-19" iyz="2.3150987623807816e-14" ixz="3.2255014631443757e-18" />
        </inertial>
        <visual name="csmall4_visual">
            <origin xyz="-0.044500001751597844 -0.016749999087958135 0.2590000007288018" rpy="-3.141592653589792 9.937682315333398e-16 7.301558552254602e-16" />
            <geometry>
                <mesh filename="meshes/csmall4.stl" scale="0.001 0.001 0.001" />
            </geometry>
        </visual>
        <collision name="csmall4_collision">
            <origin xyz="-0.044500001751597844 -0.016749999087958135 0.2590000007288018" rpy="-3.141592653589792 9.937682315333398e-16 7.301558552254602e-16" />
            <geometry>
                <mesh filename="meshes/csmall4.stl" scale="0.001 0.001 0.001" />
            </geometry>
        </collision>
    </link>
    <link name="servo8">
        <inertial>
            <origin xyz="-0.009549968521620045 0.002387494279572859 0.024964925439881967" rpy="0.0 -0.0 0.0" />
            <mass value="0.05780123871717224" />
            <inertia ixx="1.1637489216007708e-05" iyy="1.635538058944062e-05" izz="1.0629005497797377e-05" ixy="6.210436850423657e-08" iyz="-1.4284004757892906e-07" ixz="5.713601902298474e-07" />
        </inertial>
        <visual name="servo8_visual">
            <origin xyz="-0.22725000098212164 -0.01650000036945807 -0.020000001751597975" rpy="-3.141592653589792 -1.5707963267948954 0" />
            <geometry>
                <mesh filename="meshes/servo8.stl" scale="0.001 0.001 0.001" />
            </geometry>
        </visual>
        <collision name="servo8_collision">
            <origin xyz="-0.22725000098212164 -0.01650000036945807 -0.020000001751597975" rpy="-3.141592653589792 -1.5707963267948954 0" />
            <geometry>
                <mesh filename="meshes/servo8.stl" scale="0.001 0.001 0.001" />
            </geometry>
        </collision>
    </link>
    <link name="servo10">
        <inertial>
            <origin xyz="-0.00011250838944206975 -0.0010350757471211313 0.02045003415248685" rpy="-1.5557538194652854e-61 -0.0 0.0" />
            <mass value="0.05780123871717229" />
            <inertia ixx="1.6355380589490006e-05" iyy="1.0629005497729722e-05" izz="1.1637489216025435e-05" ixy="-1.4284004757451093e-07" iyz="5.713601902344519e-07" ixz="6.210436852066223e-08" />
        </inertial>
        <visual name="servo10_visual">
            <origin xyz="-0.2892500004754824 0.009999997061400298 0.08000000249665645" rpy="1.0914125846925462e-15 1.570796326794896 0" />
            <geometry>
                <mesh filename="meshes/servo10.stl" scale="0.001 0.001 0.001" />
            </geometry>
        </visual>
        <collision name="servo10_collision">
            <origin xyz="-0.2892500004754824 0.009999997061400298 0.08000000249665645" rpy="1.0914125846925462e-15 1.570796326794896 0" />
            <geometry>
                <mesh filename="meshes/servo10.stl" scale="0.001 0.001 0.001" />
            </geometry>
        </collision>
    </link>
    <link name="csmall5">
        <inertial>
            <origin xyz="-1.9061078493365357e-09 -0.019911298304645192 -0.024749997061399593" rpy="0.0 -0.0 0.0" />
            <mass value="0.0075175601892790815" />
            <inertia ixx="4.996715608188542e-06" iyy="3.897412167641834e-06" izz="1.5854743173523414e-06" ixy="2.314892255748241e-14" iyz="-9.825582188149884e-20" ixz="-6.238397656527922e-19" />
        </inertial>
        <visual name="csmall5_visual">
            <origin xyz="-0.050000002496656315 -0.29600000072880195 -0.03699999834290019" rpy="-1.5707963267948954 -7.301558552254616e-16 4.52906399314503e-16" />
            <geometry>
                <mesh filename="meshes/csmall5.stl" scale="0.001 0.001 0.001" />
            </geometry>
        </visual>
        <collision name="csmall5_collision">
            <origin xyz="-0.050000002496656315 -0.29600000072880195 -0.03699999834290019" rpy="-1.5707963267948954 -7.301558552254616e-16 4.52906399314503e-16" />
            <geometry>
                <mesh filename="meshes/csmall5.stl" scale="0.001 0.001 0.001" />
            </geometry>
        </collision>
    </link>
    <link name="servo1">
        <inertial>
            <origin xyz="0.009549966518355255 0.002387488716951498 0.02496492223011178" rpy="0.0 -1.9446922743316068e-62 0.0" />
            <mass value="0.05780123871717229" />
            <inertia ixx="1.1637489216004664e-05" iyy="1.635538058948399e-05" izz="1.0629005497773958e-05" ixy="-6.21043685011737e-08" iyz="-1.4284004757605402e-07" ixz="-5.713601902385041e-07" />
        </inertial>
        <visual name="servo1_visual">
            <origin xyz="-0.12500000182581783 0.016749996630921686 0.035999995038633055" rpy="1.5707963267948986 1.3102332426606643e-15 -4.0766001685454745e-16" />
            <geometry>
                <mesh filename="meshes/servo1.stl" scale="0.001 0.001 0.001" />
            </geometry>
        </visual>
        <collision name="servo1_collision">
            <origin xyz="-0.12500000182581783 0.016749996630921686 0.035999995038633055" rpy="1.5707963267948986 1.3102332426606643e-15 -4.0766001685454745e-16" />
            <geometry>
                <mesh filename="meshes/servo1.stl" scale="0.001 0.001 0.001" />
            </geometry>
        </collision>
    </link>
    <link name="csmall6">
        <inertial>
            <origin xyz="-1.2352658984582377e-09 4.961367565670116e-09 0.01308869880174826" rpy="0.0 -0.0 0.0" />
            <mass value="0.007517560189279023" />
            <inertia ixx="4.996715608185755e-06" iyy="1.5854743173593074e-06" izz="3.897412167641319e-06" ixy="-1.367958209815695e-19" iyz="1.747005453711994e-20" ixz="2.3151355236106924e-14" />
        </inertial>
        <visual name="csmall6_visual">
            <origin xyz="-0.1250000010807597 -0.011249995575074768 0.04999999688424148" rpy="-3.141592653589791 4.0766001685454656e-16 1.2490009069339105e-15" />
            <geometry>
                <mesh filename="meshes/csmall6.stl" scale="0.001 0.001 0.001" />
            </geometry>
        </visual>
        <collision name="csmall6_collision">
            <origin xyz="-0.1250000010807597 -0.011249995575074768 0.04999999688424148" rpy="-3.141592653589791 4.0766001685454656e-16 1.2490009069339105e-15" />
            <geometry>
                <mesh filename="meshes/csmall6.stl" scale="0.001 0.001 0.001" />
            </geometry>
        </collision>
    </link>
    <link name="servo3">
        <inertial>
            <origin xyz="-0.0023874888659615847 0.0095499633828008 0.02496492827223481" rpy="0.0 -0.0 0.0" />
            <mass value="0.05780123871717229" />
            <inertia ixx="1.6355380589487024e-05" iyy="1.163748921598597e-05" izz="1.0629005497791305e-05" ixy="6.210436850496925e-08" iyz="-5.713601902409419e-07" ixz="1.4284004757995905e-07" />
        </inertial>
        <visual name="servo3_visual">
            <origin xyz="-0.06574999677993333 0.021999995038632873 0.15500000108075956" rpy="2.012345771882042e-15 1.5707963267948952 0" />
            <geometry>
                <mesh filename="meshes/servo3.stl" scale="0.001 0.001 0.001" />
            </geometry>
        </visual>
        <collision name="servo3_collision">
            <origin xyz="-0.06574999677993333 0.021999995038632873 0.15500000108075956" rpy="2.012345771882042e-15 1.5707963267948952 0" />
            <geometry>
                <mesh filename="meshes/servo3.stl" scale="0.001 0.001 0.001" />
            </geometry>
        </collision>
    </link>
    <link name="csmall7">
        <inertial>
            <origin xyz="-1.0807555561598293e-09 4.3708202324133085e-09 0.013088698950758353" rpy="0.0 -0.0 0.0" />
            <mass value="0.007517560189279044" />
            <inertia ixx="1.585474317361896e-06" iyy="4.996715608183256e-06" izz="3.8974121676419425e-06" ixy="-2.1175823681357508e-19" iyz="-2.31508690391952e-14" ixz="6.640738306473715e-19" />
        </inertial>
        <visual name="csmall7_visual">
            <origin xyz="-0.13050000108075968 -0.021749996320132796 0.09899999703325324" rpy="-3.141592653589791 4.0742861272967434e-16 1.249000899855005e-15" />
            <geometry>
                <mesh filename="meshes/csmall7.stl" scale="0.001 0.001 0.001" />
            </geometry>
        </visual>
        <collision name="csmall7_collision">
            <origin xyz="-0.13050000108075968 -0.021749996320132796 0.09899999703325324" rpy="-3.141592653589791 4.0742861272967434e-16 1.249000899855005e-15" />
            <geometry>
                <mesh filename="meshes/csmall7.stl" scale="0.001 0.001 0.001" />
            </geometry>
        </collision>
    </link>
    <link name="csmall8">
        <inertial>
            <origin xyz="-0.01991129603275672 1.6029947946805123e-09 -0.024750001080755767" rpy="0.0 -0.0 0.0" />
            <mass value="0.0075175601892790555" />
            <inertia ixx="3.89741216764197e-06" iyy="4.996715608181982e-06" izz="1.5854743173623702e-06" ixy="-2.3150949083808716e-14" iyz="-3.290723000082957e-19" ixz="-8.673617379884035e-19" />
        </inertial>
        <visual name="csmall8_visual">
            <origin xyz="-0.14699999845690861 -0.021749999087958237 -0.1552500010807598" rpy="-3.141592653589792 -1.5707963267948952 0" />
            <geometry>
                <mesh filename="meshes/csmall8.stl" scale="0.001 0.001 0.001" />
            </geometry>
        </visual>
        <collision name="csmall8_collision">
            <origin xyz="-0.14699999845690861 -0.021749999087958237 -0.1552500010807598" rpy="-3.141592653589792 -1.5707963267948952 0" />
            <geometry>
                <mesh filename="meshes/csmall8.stl" scale="0.001 0.001 0.001" />
            </geometry>
        </collision>
    </link>
    <link name="Comp2">
        <inertial>
            <origin xyz="-1.0807555739233977e-09 0.0052341478323971735 0.007101232491757585" rpy="0.0 -0.0 0.0" />
            <mass value="0.024635392744770463" />
            <inertia ixx="1.4596525160541973e-06" iyy="6.18083552493022e-06" izz="6.812286694459326e-06" ixy="-8.487270131488089e-19" iyz="-3.052234876525112e-07" ixz="2.3310346708438345e-18" />
        </inertial>
        <visual name="Comp2_visual">
            <origin xyz="-0.13050000108075963 -0.011309445863593193 0.11331588555303214" rpy="-3.141592653589791 4.069010736003487e-16 1.2490009926756353e-15" />
            <geometry>
                <mesh filename="meshes/Comp2.stl" scale="0.001 0.001 0.001" />
            </geometry>
        </visual>
        <collision name="Comp2_collision">
            <origin xyz="-0.13050000108075963 -0.011309445863593193 0.11331588555303214" rpy="-3.141592653589791 4.069010736003487e-16 1.2490009926756353e-15" />
            <geometry>
                <mesh filename="meshes/Comp2.stl" scale="0.001 0.001 0.001" />
            </geometry>
        </collision>
    </link>
    <link name="servo5">
        <inertial>
            <origin xyz="0.0015104706116613898 -0.059836430778758685 -0.011754290813263677" rpy="0.0 -0.0 0.0" />
            <mass value="0.06069923871717226" />
            <inertia ixx="1.4693730397505583e-05" iyy="1.2227175300407941e-05" izz="2.003750615803138e-05" ixy="7.085129238092007e-07" iyz="-1.0846499523494262e-06" ixz="-8.478544707405425e-08" />
        </inertial>
        <visual name="servo5_visual">
            <origin xyz="-0.1284488710807597 -0.21663231820358875 -0.03199999780645829" rpy="-1.5707963267948952 -1.4710456866728654e-15 1.8463958064169038e-16" />
            <geometry>
                <mesh filename="meshes/servo5.stl" scale="0.001 0.001 0.001" />
            </geometry>
        </visual>
        <collision name="servo5_collision">
            <origin xyz="-0.1284488710807597 -0.21663231820358875 -0.03199999780645829" rpy="-1.5707963267948952 -1.4710456866728654e-15 1.8463958064169038e-16" />
            <geometry>
                <mesh filename="meshes/servo5.stl" scale="0.001 0.001 0.001" />
            </geometry>
        </collision>
    </link>
    <link name="csmall9">
        <inertial>
            <origin xyz="-2.928775373334247e-09 2.7840902805387205e-09 0.013088702348303229" rpy="0.0 -0.0 0.0" />
            <mass value="0.007517560189288569" />
            <inertia ixx="1.5854743173678997e-06" iyy="4.9967156081874575e-06" izz="3.897412167649125e-06" ixy="-6.2511031507367365e-19" iyz="2.3151016422928022e-14" ixz="2.710505431213761e-19" />
        </inertial>
        <visual name="csmall9_visual">
            <origin xyz="-0.1305000029287901 -0.01674999908795828 0.2590000007288016" rpy="-3.141592653589792 -3.7459185059836284e-17 1.6930925415094461e-15" />
            <geometry>
                <mesh filename="meshes/csmall9.stl" scale="0.001 0.001 0.001" />
            </geometry>
        </visual>
        <collision name="csmall9_collision">
            <origin xyz="-0.1305000029287901 -0.01674999908795828 0.2590000007288016" rpy="-3.141592653589792 -3.7459185059836284e-17 1.6930925415094461e-15" />
            <geometry>
                <mesh filename="meshes/csmall9.stl" scale="0.001 0.001 0.001" />
            </geometry>
        </collision>
    </link>
    <link name="servo7">
        <inertial>
            <origin xyz="-0.009549968521619831 -0.0023874942795729104 0.02496493012026555" rpy="0.0 -0.0 0.0" />
            <mass value="0.05780123871717224" />
            <inertia ixx="1.1637489216011774e-05" iyy="1.6355380589428477e-05" izz="1.0629005497811688e-05" ixy="-6.210436850401973e-08" iyz="1.428400475718411e-07" ixz="5.713601902526157e-07" />
        </inertial>
        <visual name="servo7_visual">
            <origin xyz="-0.22725000098212136 0.01650000036945815 0.1550000029287901" rpy="1.3288061796878798e-15 1.5707963267948952 0" />
            <geometry>
                <mesh filename="meshes/servo7.stl" scale="0.001 0.001 0.001" />
            </geometry>
        </visual>
        <collision name="servo7_collision">
            <origin xyz="-0.22725000098212136 0.01650000036945815 0.1550000029287901" rpy="1.3288061796878798e-15 1.5707963267948952 0" />
            <geometry>
                <mesh filename="meshes/servo7.stl" scale="0.001 0.001 0.001" />
            </geometry>
        </collision>
    </link>
    <link name="servo9">
        <inertial>
            <origin xyz="-0.00011250838944196318 0.0010350757471211725 0.020450029472102643" rpy="-1.5557538194652854e-61 -0.0 0.0" />
            <mass value="0.05780123871717229" />
            <inertia ixx="1.6355380589495047e-05" iyy="1.0629005497726253e-05" izz="1.1637489216028037e-05" ixy="1.428400475743212e-07" iyz="-5.713601902454057e-07" ixz="6.210436848683512e-08" />
        </inertial>
        <visual name="servo9_visual">
            <origin xyz="-0.2892500004754823 -0.009999997061400298 -0.09500000218373193" rpy="-3.1415926535897922 -1.570796326794896 0" />
            <geometry>
                <mesh filename="meshes/servo9.stl" scale="0.001 0.001 0.001" />
            </geometry>
        </visual>
        <collision name="servo9_collision">
            <origin xyz="-0.2892500004754823 -0.009999997061400298 -0.09500000218373193" rpy="-3.1415926535897922 -1.570796326794896 0" />
            <geometry>
                <mesh filename="meshes/servo9.stl" scale="0.001 0.001 0.001" />
            </geometry>
        </collision>
    </link>
    <link name="csmall10">
        <inertial>
            <origin xyz="-2.7742760799753798e-09 -0.019911298304619685 -0.02474999706141061" rpy="0.0 -0.0 0.0" />
            <mass value="0.0075175601892885895" />
            <inertia ixx="4.996715608197107e-06" iyy="3.897412167649342e-06" izz="1.585474317356136e-06" ixy="-2.3153137393427947e-14" iyz="1.5077186461126546e-18" ixz="-7.352245982167327e-19" />
        </inertial>
        <visual name="csmall10_visual">
            <origin xyz="-0.1250000021837316 -0.29600000072880184 -0.036999998342900325" rpy="-1.5707963267948954 -1.6930925415094453e-15 2.0816681711721522e-16" />
            <geometry>
                <mesh filename="meshes/csmall10.stl" scale="0.001 0.001 0.001" />
            </geometry>
        </visual>
        <collision name="csmall10_collision">
            <origin xyz="-0.1250000021837316 -0.29600000072880184 -0.036999998342900325" rpy="-1.5707963267948954 -1.6930925415094453e-15 2.0816681711721522e-16" />
            <geometry>
                <mesh filename="meshes/csmall10.stl" scale="0.001 0.001 0.001" />
            </geometry>
        </collision>
    </link>
    <link name="Comp3">
        <inertial>
            <origin xyz="-2.340192111205397e-09 -2.9386003363995885e-09 0.015000001978838605" rpy="0.0 -0.0 0.0" />
            <mass value="0.324126" />
            <inertia ixx="0.00012154725000009664" iyy="0.0003511364999996894" izz="0.0004240648500000899" ixy="3.6700243538634325e-17" iyz="8.998878031629687e-18" ixz="-1.0928757898653885e-16" />
        </inertial>
        <visual name="Comp3_visual">
            <origin xyz="-0.08790239544049004 0.029999997061400968 -0.30209760492087634" rpy="1.4266571980938258e-15 -3.308896091966322e-16 -7.021478737325885e-16" />
            <geometry>
                <mesh filename="meshes/Comp3.stl" scale="0.001 0.001 0.001" />
            </geometry>
        </visual>
        <collision name="Comp3_collision">
            <origin xyz="-0.08790239544049004 0.029999997061400968 -0.30209760492087634" rpy="1.4266571980938258e-15 -3.308896091966322e-16 -7.021478737325885e-16" />
            <geometry>
                <mesh filename="meshes/Comp3.stl" scale="0.001 0.001 0.001" />
            </geometry>
        </collision>
    </link>
    <link name="ankel2">
        <inertial>
            <origin xyz="-1.8258131717630023e-09 4.961367401357108e-09 0.0008749966309217045" rpy="0.0 -0.0 1.9446922743316068e-62" />
            <mass value="0.022345050000000005" />
            <inertia ixx="2.681976264297074e-05" iyy="7.873022330461303e-06" izz="3.468137968750182e-05" ixy="-4.760325163569168e-19" iyz="2.2869889575866112e-20" ixz="1.6339265552535454e-18" />
        </inertial>
        <visual name="ankel2_visual">
            <origin xyz="-0.14250000182581812 -0.00999999503863305 0.0017499966309217736" rpy="-3.141592653589791 4.2674197509029134e-16 1.310233242660665e-15" />
            <geometry>
                <mesh filename="meshes/ankel2.stl" scale="0.001 0.001 0.001" />
            </geometry>
        </visual>
        <collision name="ankel2_collision">
            <origin xyz="-0.14250000182581812 -0.00999999503863305 0.0017499966309217736" rpy="-3.141592653589791 4.2674197509029134e-16 1.310233242660665e-15" />
            <geometry>
                <mesh filename="meshes/ankel2.stl" scale="0.001 0.001 0.001" />
            </geometry>
        </collision>
    </link>
    <link name="base_link">
        <inertial>
            <origin xyz="0.0875000013038567 -0.0009999999999999115 0.2943680743872477" rpy="0.0 0.0 0.0" />
            <mass value="0.01755626878248209" />
            <inertia ixx="1.5391454563691157e-06" iyy="1.5991293939087798e-06" izz="1.2304018564035566e-06" ixy="1.7481631746319775e-18" iyz="2.708527954745572e-19" ixz="-5.426260569944666e-18" />
        </inertial>
        <visual name="base_link_visual">
            <origin xyz="0.0 0.0 0.0" rpy="0.0 0.0 0.0" />
            <geometry>
                <mesh filename="meshes/base_link.stl" scale="0.001 0.001 0.001" />
            </geometry>
        </visual>
        <collision name="base_link_collision">
            <origin xyz="0.0 0.0 0.0" rpy="0.0 0.0 0.0" />
            <geometry>
                <mesh filename="meshes/base_link.stl" scale="0.001 0.001 0.001" />
            </geometry>
        </collision>
    </link>
    <link name="Comp4">
        <inertial>
            <origin xyz="-2.3401922533139443e-09 -2.9386003908005165e-09 0.030000001978839067" rpy="0.0 -0.0 0.0" />
            <mass value="0.039288000000000003" />
            <inertia ixx="1.3095999999972012e-05" iyy="1.3095999999935583e-05" izz="2.6191999999999427e-06" ixy="1.7414997395548415e-18" iyz="-1.2115959277525512e-17" ixz="4.119968255444917e-18" />
        </inertial>
        <visual name="Comp4_visual">
            <origin xyz="-0.09858072889946762 -0.008716800000000349 -0.35762684908396125" rpy="-8.3421645302472e-16 1.1102230246251527e-16 -7.02147873732588e-16" />
            <geometry>
                <mesh filename="meshes/Comp4.stl" scale="0.001 0.001 0.001" />
            </geometry>
        </visual>
        <collision name="Comp4_collision">
            <origin xyz="-0.09858072889946762 -0.008716800000000349 -0.35762684908396125" rpy="-8.3421645302472e-16 1.1102230246251527e-16 -7.02147873732588e-16" />
            <geometry>
                <mesh filename="meshes/Comp4.stl" scale="0.001 0.001 0.001" />
            </geometry>
        </collision>
    </link>
    <link name="sensor2">
        <inertial>
            <origin xyz="-2.8545688746106635e-09 -4.961367416900231e-09 0.0010000033690786925" rpy="0.0 -0.0 0.0" />
            <mass value="0.00111" />
            <inertia ixx="3.736999999999224e-08" iyy="2.1182500000000792e-08" izz="5.781249999998658e-08" ixy="-1.164670302474663e-21" iyz="-6.61744490042422e-23" ixz="-2.1175823681357513e-22" />
        </inertial>
        <visual name="sensor2_visual">
            <origin xyz="-0.10238803388935502 0.14515758070769377 3.3690790379736767e-09" rpy="2.377324588427018e-15 -1.577721810442026e-30 6.881682016646131e-16" />
            <geometry>
                <mesh filename="meshes/sensor2.stl" scale="0.001 0.001 0.001" />
            </geometry>
        </visual>
        <collision name="sensor2_collision">
            <origin xyz="-0.10238803388935502 0.14515758070769377 3.3690790379736767e-09" rpy="2.377324588427018e-15 -1.577721810442026e-30 6.881682016646131e-16" />
            <geometry>
                <mesh filename="meshes/sensor2.stl" scale="0.001 0.001 0.001" />
            </geometry>
        </collision>
    </link>
    <link name="sensor7">
        <inertial>
            <origin xyz="1.9788393501585233e-09 -2.9386003363995885e-09 0.0010000023401924986" rpy="-9.723461371658034e-63 -0.0 0.0" />
            <mass value="0.00111" />
            <inertia ixx="2.118250000004018e-08" iyy="3.7369999999890173e-08" izz="5.78124999998735e-08" ixy="6.3527471044072525e-21" iyz="-4.219894877684143e-40" ixz="-6.776263578034403e-21" />
        </inertial>
        <visual name="sensor7_visual">
            <origin xyz="0.1451575876479007 0.10238802809618537 2.3401924131860596e-09" rpy="-1.1102230246251906e-16 -7.021478737325589e-16 -1.5707963267948977" />
            <geometry>
                <mesh filename="meshes/sensor7.stl" scale="0.001 0.001 0.001" />
            </geometry>
        </visual>
        <collision name="sensor7_collision">
            <origin xyz="0.1451575876479007 0.10238802809618537 2.3401924131860596e-09" rpy="-1.1102230246251906e-16 -7.021478737325589e-16 -1.5707963267948977" />
            <geometry>
                <mesh filename="meshes/sensor7.stl" scale="0.001 0.001 0.001" />
            </geometry>
        </collision>
    </link>
    <link name="sensor4">
        <inertial>
            <origin xyz="-3.599627156347651e-09 -1.7964164378270198e-09 0.0009999978064577308" rpy="0.0 -0.0 0.0" />
            <mass value="0.00111" />
            <inertia ixx="3.7369999999995205e-08" iyy="2.1182500000001216e-08" izz="5.781249999998531e-08" ixy="0.0" iyz="0.0" ixz="-4.235164736271502e-22" />
        </inertial>
        <visual name="sensor4_visual">
            <origin xyz="-0.1023880346344131 0.14515758387264488 -2.193541939199406e-09" rpy="1.5881393422555345e-15 9.52223853932184e-16 -6.492997941912091e-16" />
            <geometry>
                <mesh filename="meshes/sensor4.stl" scale="0.001 0.001 0.001" />
            </geometry>
        </visual>
        <collision name="sensor4_collision">
            <origin xyz="-0.1023880346344131 0.14515758387264488 -2.193541939199406e-09" rpy="1.5881393422555345e-15 9.52223853932184e-16 -6.492997941912091e-16" />
            <geometry>
                <mesh filename="meshes/sensor4.stl" scale="0.001 0.001 0.001" />
            </geometry>
        </collision>
    </link>
    <link name="sensor1">
        <inertial>
            <origin xyz="-1.8258132783444125e-09 -4.961367470190936e-09 0.0010000033690792255" rpy="0.0 -0.0 -1.9446922743316068e-62" />
            <mass value="0.00111" />
            <inertia ixx="3.7369999999986735e-08" iyy="2.1182500000004604e-08" izz="5.781249999998531e-08" ixy="1.4823076576950256e-21" iyz="-1.1911400820763599e-22" ixz="2.850376317692965e-39" />
        </inertial>
        <visual name="sensor1_visual">
            <origin xyz="-0.10238803286059911 0.1451575807076939 3.3690795175900234e-09" rpy="2.0263332571933324e-15 2.415886522239338e-30 -1.3102332426606636e-15" />
            <geometry>
                <mesh filename="meshes/sensor1.stl" scale="0.001 0.001 0.001" />
            </geometry>
        </visual>
        <collision name="sensor1_collision">
            <origin xyz="-0.10238803286059911 0.1451575807076939 3.3690795175900234e-09" rpy="2.0263332571933324e-15 2.415886522239338e-30 -1.3102332426606636e-15" />
            <geometry>
                <mesh filename="meshes/sensor1.stl" scale="0.001 0.001 0.001" />
            </geometry>
        </collision>
    </link>
    <link name="sensor5">
        <inertial>
            <origin xyz="3.2693061058353123e-09 -7.320060968485365e-10 0.0009999970712144446" rpy="0.0 -0.0 0.0" />
            <mass value="0.00111" />
            <inertia ixx="2.118250000001138e-08" iyy="3.7369999999998594e-08" izz="5.781250000000903e-08" ixy="1.6940658945086007e-21" iyz="2.117582368135751e-22" ixz="2.2803010541548517e-38" />
        </inertial>
        <visual name="sensor5_visual">
            <origin xyz="-0.14515758239975501 -0.1023880317667923 -2.928785498568232e-09" rpy="-3.7459185059834885e-17 5.413374510864967e-16 1.570796326794898" />
            <geometry>
                <mesh filename="meshes/sensor5.stl" scale="0.001 0.001 0.001" />
            </geometry>
        </visual>
        <collision name="sensor5_collision">
            <origin xyz="-0.14515758239975501 -0.1023880317667923 -2.928785498568232e-09" rpy="-3.7459185059834885e-17 5.413374510864967e-16 1.570796326794898" />
            <geometry>
                <mesh filename="meshes/sensor5.stl" scale="0.001 0.001 0.001" />
            </geometry>
        </collision>
    </link>
    <link name="sensor3">
        <inertial>
            <origin xyz="-1.0807558759040603e-09 -1.796416579935567e-09 0.000999997806457751" rpy="0.0 -0.0 0.0" />
            <mass value="0.00111" />
            <inertia ixx="3.736999999999182e-08" iyy="2.1182500000004604e-08" izz="5.78124999999887e-08" ixy="1.4739866014051436e-38" iyz="8.470329472543003e-22" ixz="6.741874483203176e-39" />
        </inertial>
        <visual name="sensor3_visual">
            <origin xyz="-0.10238803211554187 0.14515758387264469 -2.1935418703655784e-09" rpy="1.5952950765962468e-15 1.4098135165394976e-15 -1.8463958064169048e-16" />
            <geometry>
                <mesh filename="meshes/sensor3.stl" scale="0.001 0.001 0.001" />
            </geometry>
        </visual>
        <collision name="sensor3_collision">
            <origin xyz="-0.10238803211554187 0.14515758387264469 -2.1935418703655784e-09" rpy="1.5952950765962468e-15 1.4098135165394976e-15 -1.8463958064169048e-16" />
            <geometry>
                <mesh filename="meshes/sensor3.stl" scale="0.001 0.001 0.001" />
            </geometry>
        </collision>
    </link>
    <link name="sensor6">
        <inertial>
            <origin xyz="3.2693058926724918e-09 7.320062211935153e-10 0.0010000017515983074" rpy="0.0 -0.0 0.0" />
            <mass value="0.00111" />
            <inertia ixx="2.1182499999999733e-08" iyy="3.7370000000012146e-08" izz="5.781250000000903e-08" ixy="4.235164736271502e-21" iyz="-2.6469779601696868e-23" ixz="-1.3254499705944145e-52" />
        </inertial>
        <visual name="sensor6_visual">
            <origin xyz="0.14515758893836725 0.10238803176679208 1.751598350807626e-09" rpy="9.937682315333412e-16 -9.85426449178317e-16 -1.570796326794898" />
            <geometry>
                <mesh filename="meshes/sensor6.stl" scale="0.001 0.001 0.001" />
            </geometry>
        </visual>
        <collision name="sensor6_collision">
            <origin xyz="0.14515758893836725 0.10238803176679208 1.751598350807626e-09" rpy="9.937682315333412e-16 -9.85426449178317e-16 -1.570796326794898" />
            <geometry>
                <mesh filename="meshes/sensor6.stl" scale="0.001 0.001 0.001" />
            </geometry>
        </collision>
    </link>
    <link name="Comp5">
        <inertial>
            <origin xyz="-2.340192200023239e-09 1.9788384975072405e-09 0.012500002938601562" rpy="0.0 -0.0 0.0" />
            <mass value="0.15756125" />
            <inertia ixx="2.4290692708383438e-05" iyy="0.00016708057552068602" izz="0.00017495863802087508" ixy="-1.734723475976807e-17" iyz="4.7704895589362195e-18" ixz="5.366800753803247e-17" />
        </inertial>
        <visual name="Comp5_visual">
            <origin xyz="-0.08790239544049182 -0.017499998021162533 0.3320976098383161" rpy="-3.1415926535897913 -4.849288164901163e-15 3.308896091966263e-16" />
            <geometry>
                <mesh filename="meshes/Comp5.stl" scale="0.001 0.001 0.001" />
            </geometry>
        </visual>
        <collision name="Comp5_collision">
            <origin xyz="-0.08790239544049182 -0.017499998021162533 0.3320976098383161" rpy="-3.1415926535897913 -4.849288164901163e-15 3.308896091966263e-16" />
            <geometry>
                <mesh filename="meshes/Comp5.stl" scale="0.001 0.001 0.001" />
            </geometry>
        </collision>
    </link>
    <joint name="servo2_Rigid-85" type="fixed">
        <origin xyz="-0.01 0.015 0.025999999999999995" rpy="-1.5707963267948966 -4.4320160466905134e-32 9.860761315262648e-32" />
        <parent link="servo2" />
        <child link="ankel1" />
    </joint>
    <joint name="servo1_Rigid-86" type="fixed">
        <origin xyz="0.01 0.015 0.025999999999999995" rpy="-1.5707963267948966 -5.702138497759798e-33 -9.860761315262648e-32" />
        <parent link="servo1" />
        <child link="ankel2" />
    </joint>
    <joint name="servo2_val" type="fixed">
        <origin xyz="0.0 0.024749999999999998 0.033" rpy="1.5707963267948966 9.860761315262648e-32 1.4739898164836845e-31" />
        <parent link="csmall1" />
        <child link="servo2" />
        <axis xyz="-7.992343164533666e-32 0.0 1.0" />
        <limit lower="-0.872665" upper="0.872665" effort="1000000" velocity="1000000" />
    </joint>
    <joint name="servo1_val" type="fixed">
        <origin xyz="0.0 0.024749999999999998 0.033" rpy="1.5707963267948966 -4.930380657631324e-32 -1.97324315788137e-31" />
        <parent link="csmall6" />
        <child link="servo1" />
        <axis xyz="3.1492006061600383e-32 -3.944304526105059e-31 1.0" />
        <limit lower="-0.872665" upper="0.872665" effort="1000000" velocity="1000000" />
    </joint>
    <joint name="servo3_Rigid-89" type="fixed">
        <origin xyz="-0.015 0.01 0.026000000000000016" rpy="-3.141592653589793 1.5707963267948966 0" />
        <parent link="servo3" />
        <child link="csmall6" />
    </joint>
    <joint name="servo4_Rigid-90" type="fixed">
        <origin xyz="-0.015 -0.01 0.026000000000000002" rpy="-0.0 -1.5707963267948966 0" />
        <parent link="servo4" />
        <child link="csmall1" />
    </joint>
    <joint name="servo4_val" type="revolute">
        <origin xyz="-0.02475 0.0 0.033" rpy="1.9734305032509502e-31 1.5707963267948966 0" />
        <parent link="csmall2" />
        <child link="servo4" />
        <axis xyz="7.888609052210118e-31 5.227728254181639e-31 1.0" />
        <limit lower="-1.570796" upper="1.570796" effort="1000000" velocity="1000000" />
    </joint>
    <joint name="Comp1_Rigid-92" type="fixed">
        <origin xyz="0.0 0.01046829 0.014202469999999998" rpy="1.9721522630525295e-31 -5.616505753082788e-63 -2.84790675563228e-32" />
        <parent link="Comp1" />
        <child link="csmall2" />
    </joint>
    <joint name="csmall3_Rigid-93" type="fixed">
        <origin xyz="-0.03300000000000001 0.0 -0.02475" rpy="-3.141592653589793 1.5707963267948966 0" />
        <parent link="csmall3" />
        <child link="Comp1" />
    </joint>
    <joint name="servo6_val" type="revolute">
        <origin xyz="-0.026551129999999996 -0.07088231999999998 -0.01" rpy="-1.5707963267948966 -0.0 1.5707963267948966" />
        <parent link="servo6" />
        <child link="csmall3" />
        <axis xyz="0.0 -1.159031063722169e-33 1.0" />
        <limit lower="-1.570796" upper="1.570796" effort="1000000" velocity="1000000" />
    </joint>
    <joint name="servo8_Rigid-95" type="fixed">
        <origin xyz="-0.01 0.015 0.025999999999999995" rpy="-1.5707963267948966 -1.5707963267948966 0" />
        <parent link="servo8" />
        <child link="servo6" />
    </joint>
    <joint name="servo8_val" type="revolute">
        <origin xyz="-0.024749999999999998 0.0 0.03300000000000001" rpy="7.992286107048302e-32 1.5707963267948966 0" />
        <parent link="csmall4" />
        <child link="servo8" />
        <axis xyz="0.0 2.7962383350627467e-31 1.0" />
        <limit lower="-1.570796" upper="1.570796" effort="1000000" velocity="1000000" />
    </joint>
    <joint name="csmall5_Rigid-97" type="fixed">
        <origin xyz="0.0 -0.03300000000000001 -0.02475" rpy="1.5707963267948966 -2.1340054758171858e-32 9.860761315262648e-32" />
        <parent link="csmall5" />
        <child link="csmall4" />
    </joint>
    <joint name="servo10_val" type="revolute">
        <origin xyz="-0.0025 -0.026000000000000002 0.03" rpy="1.5707963267948966 1.5707963267948966 0" />
        <parent link="servo10" />
        <child link="csmall5" />
        <axis xyz="2.7286503733033063e-32 -0.0 1.0" />
        <limit lower="-1.570796" upper="0.523599" effort="1000000" velocity="1000000" />
    </joint>
    <joint name="base_link_Rigid-99" type="fixed">
        <origin xyz="0.07700000364404411 -0.0009999970613996456 0.2943680748627" rpy="7.021478737325863e-16 -1.5707963267948928 0" />
        <parent link="base_link" />
        <child link="servo10" />
    </joint>
    <joint name="servo3_val" type="revolute">
        <origin xyz="0.024750000000000015 0.0 0.033" rpy="3.141592653589793 1.5707963267948966 0" />
        <parent link="csmall7" />
        <child link="servo3" />
        <axis xyz="-7.888609052210118e-31 1.6743631100220177e-31 1.0" />
        <limit lower="-1.570796" upper="1.570796" effort="1000000" velocity="1000000" />
    </joint>
    <joint name="Comp2_Rigid-101" type="fixed">
        <origin xyz="0.0 0.01046829 0.014202469999999998" rpy="-3.944304526105059e-31 -0.0 -6.221834973550431e-32" />
        <parent link="Comp2" />
        <child link="csmall7" />
    </joint>
    <joint name="csmall8_Rigid-102" type="fixed">
        <origin xyz="-0.03300000000000001 0.0 -0.024750000000000015" rpy="-1.9721522630525295e-31 -1.5707963267948966 0" />
        <parent link="csmall8" />
        <child link="Comp2" />
    </joint>
    <joint name="servo5_val" type="revolute">
        <origin xyz="0.02655113000000002 -0.07088231999999998 -0.01" rpy="1.5707963267948966 -1.9721522630525295e-31 1.5707963267948966" />
        <parent link="servo5" />
        <child link="csmall8" />
        <axis xyz="-3.944304526105059e-31 -7.727863396283102e-32 1.0" />
        <limit lower="-1.570796" upper="1.570796" effort="1000000" velocity="1000000" />
    </joint>
    <joint name="servo7_Rigid-104" type="fixed">
        <origin xyz="-0.01 -0.015 0.025999999999999995" rpy="1.5707963267948966 1.5707963267948966 0" />
        <parent link="servo7" />
        <child link="servo5" />
    </joint>
    <joint name="servo7_val" type="revolute">
        <origin xyz="0.024749999999999998 0.0 0.03300000000000001" rpy="3.141592653589793 1.5707963267948966 0" />
        <parent link="csmall9" />
        <child link="servo7" />
        <axis xyz="-3.944304526105059e-31 -1.8538350212600917e-31 1.0" />
        <limit lower="-1.570796" upper="1.570796" effort="1000000" velocity="1000000" />
    </joint>
    <joint name="csmall10_Rigid-106" type="fixed">
        <origin xyz="0.0 -0.03300000000000001 -0.02475" rpy="1.5707963267948966 2.784067740973774e-31 0.0" />
        <parent link="csmall10" />
        <child link="csmall9" />
    </joint>
    <joint name="servo9_val" type="revolute">
        <origin xyz="-0.0025 0.026000000000000002 0.03" rpy="-1.5707963267948966 -1.5707963267948966 0" />
        <parent link="servo9" />
        <child link="csmall10" />
        <axis xyz="2.728650373303245e-32 -0.0 1.0" />
        <limit lower="-0.523599" upper="1.570796" effort="1000000" velocity="1000000" />
    </joint>
    <joint name="base_link_Rigid-108" type="fixed">
        <origin xyz="0.09800000364404338 -0.00099999706139963 0.2943680748627" rpy="-3.1415926535897927 -1.5707963267948928 0" />
        <parent link="base_link" />
        <child link="servo9" />
    </joint>
    <joint name="base_link_Rigid-109" type="fixed">
        <origin xyz="0.08750000364404383 -0.0009999970613996235 0.3071355248626996" rpy="-1.2577698011349667e-15 4.2674197509029474e-16 7.021478737325924e-16" />
        <parent link="base_link" />
        <child link="Comp3" />
    </joint>
    <joint name="Comp3_Rigid-121" type="fixed">
        <origin xyz="0.0 0.0 0.029999999999999964" rpy="1.9721522630525295e-31 -2.3367221232531265e-63 1.1848588808433634e-32" />
        <parent link="Comp3" />
        <child link="Comp4" />
    </joint>
    <joint name="servo1_Rigid-139" type="fixed">
        <origin xyz="0.01 -0.01 0.025999999999999995" rpy="1.5707963267948966 -5.702138497759798e-33 -9.860761315262648e-32" />
        <parent link="servo1" />
        <child link="sensor1" />
    </joint>
    <joint name="servo2_Rigid-140" type="fixed">
        <origin xyz="-0.01 -0.01 0.025999999999999995" rpy="1.5707963267948966 -4.4320160466905134e-32 9.860761315262648e-32" />
        <parent link="servo2" />
        <child link="sensor2" />
    </joint>
    <joint name="servo6_Rigid-141" type="fixed">
        <origin xyz="-0.0005511299999999953 -0.06088231999999998 -0.025" rpy="3.141592653589793 6.518783011447375e-32 -9.860761315262648e-32" />
        <parent link="servo6" />
        <child link="sensor4" />
    </joint>
    <joint name="servo5_Rigid-142" type="fixed">
        <origin xyz="0.0005511300000000042 -0.06088231999999998 -0.025" rpy="-3.141592653589793 2.500881773550205e-31 4.93211964933386e-62" />
        <parent link="servo5" />
        <child link="sensor3" />
    </joint>
    <joint name="Comp4_Rigid-145" type="fixed">
        <origin xyz="-0.01 0.0 0.03" rpy="-7.125610011907874e-33 -1.5707963267948966 0" />
        <parent link="Comp4" />
        <child link="sensor7" />
    </joint>
    <joint name="csmall9_Rigid-146" type="fixed">
        <origin xyz="0.026500000000000003 -6.399999999995298e-07 0.022273630000000006" rpy="-3.0089626695796493e-31 1.5707963267948966 0" />
        <parent link="csmall9" />
        <child link="sensor5" />
    </joint>
    <joint name="csmall4_Rigid-147" type="fixed">
        <origin xyz="-0.0265 -6.399999999995298e-07 0.022273630000000006" rpy="-3.141592653589793 1.5707963267948966 0" />
        <parent link="csmall4" />
        <child link="sensor6" />
    </joint>
    <joint name="Comp3_Rigid-148" type="fixed">
        <origin xyz="0.0 -0.03 0.014999999999999965" rpy="1.5707963267948966 -2.3367221232531265e-63 1.1848588808433634e-32" />
        <parent link="Comp3" />
        <child link="Comp5" />
    </joint>
</robot>